[2022-02-02 21:47:28,795] {taskinstance.py:1032} INFO - Dependencies all met for <TaskInstance: Question4_Zone.local_to_gcs_task manual__2022-02-02T21:47:18.420133+00:00 [queued]>
[2022-02-02 21:47:28,852] {taskinstance.py:1032} INFO - Dependencies all met for <TaskInstance: Question4_Zone.local_to_gcs_task manual__2022-02-02T21:47:18.420133+00:00 [queued]>
[2022-02-02 21:47:28,853] {taskinstance.py:1238} INFO - 
--------------------------------------------------------------------------------
[2022-02-02 21:47:28,853] {taskinstance.py:1239} INFO - Starting attempt 1 of 1
[2022-02-02 21:47:28,853] {taskinstance.py:1240} INFO - 
--------------------------------------------------------------------------------
[2022-02-02 21:47:28,908] {taskinstance.py:1259} INFO - Executing <Task(PythonOperator): local_to_gcs_task> on 2022-02-02 21:47:18.420133+00:00
[2022-02-02 21:47:28,915] {standard_task_runner.py:52} INFO - Started process 2391 to run task
[2022-02-02 21:47:28,927] {standard_task_runner.py:76} INFO - Running: ['***', 'tasks', 'run', 'Question4_Zone', 'local_to_gcs_task', 'manual__2022-02-02T21:47:18.420133+00:00', '--job-id', '376', '--raw', '--subdir', 'DAGS_FOLDER/dag_questions4.py', '--cfg-path', '/tmp/tmpz6fcsrrj', '--error-file', '/tmp/tmp1aibzs8r']
[2022-02-02 21:47:28,942] {standard_task_runner.py:77} INFO - Job 376: Subtask local_to_gcs_task
[2022-02-02 21:47:29,204] {logging_mixin.py:109} INFO - Running <TaskInstance: Question4_Zone.local_to_gcs_task manual__2022-02-02T21:47:18.420133+00:00 [running]> on host d574c7c5b085
[2022-02-02 21:47:29,373] {taskinstance.py:1426} INFO - Exporting the following env vars:
AIRFLOW_CTX_DAG_OWNER=***
AIRFLOW_CTX_DAG_ID=Question4_Zone
AIRFLOW_CTX_TASK_ID=local_to_gcs_task
AIRFLOW_CTX_EXECUTION_DATE=2022-02-02T21:47:18.420133+00:00
AIRFLOW_CTX_DAG_RUN_ID=manual__2022-02-02T21:47:18.420133+00:00
[2022-02-02 21:47:29,401] {taskinstance.py:1700} ERROR - Task failed with exception
Traceback (most recent call last):
  File "/home/airflow/.local/lib/python3.7/site-packages/airflow/models/taskinstance.py", line 1329, in _run_raw_task
    self._execute_task_with_callbacks(context)
  File "/home/airflow/.local/lib/python3.7/site-packages/airflow/models/taskinstance.py", line 1455, in _execute_task_with_callbacks
    result = self._execute_task(context, self.task)
  File "/home/airflow/.local/lib/python3.7/site-packages/airflow/models/taskinstance.py", line 1511, in _execute_task
    result = execute_callable(context=context)
  File "/home/airflow/.local/lib/python3.7/site-packages/airflow/operators/python.py", line 174, in execute
    return_value = self.execute_callable()
  File "/home/airflow/.local/lib/python3.7/site-packages/airflow/operators/python.py", line 185, in execute_callable
    return self.python_callable(*self.op_args, **self.op_kwargs)
  File "/opt/airflow/dags/ingest_fhv.py", line 40, in upload_to_gcs
    blob.upload_from_filename(local_file)
  File "/home/airflow/.local/lib/python3.7/site-packages/google/cloud/storage/blob.py", line 2720, in upload_from_filename
    with open(filename, "rb") as file_obj:
FileNotFoundError: [Errno 2] No such file or directory: '/opt/airflowtaxi+_zone_lookup.parquettaxi+_zone_lookup.parquet'
[2022-02-02 21:47:29,438] {taskinstance.py:1277} INFO - Marking task as FAILED. dag_id=Question4_Zone, task_id=local_to_gcs_task, execution_date=20220202T214718, start_date=20220202T214728, end_date=20220202T214729
[2022-02-02 21:47:29,484] {standard_task_runner.py:92} ERROR - Failed to execute job 376 for task local_to_gcs_task
Traceback (most recent call last):
  File "/home/airflow/.local/lib/python3.7/site-packages/airflow/task/task_runner/standard_task_runner.py", line 85, in _start_by_fork
    args.func(args, dag=self.dag)
  File "/home/airflow/.local/lib/python3.7/site-packages/airflow/cli/cli_parser.py", line 48, in command
    return func(*args, **kwargs)
  File "/home/airflow/.local/lib/python3.7/site-packages/airflow/utils/cli.py", line 92, in wrapper
    return f(*args, **kwargs)
  File "/home/airflow/.local/lib/python3.7/site-packages/airflow/cli/commands/task_command.py", line 298, in task_run
    _run_task_by_selected_method(args, dag, ti)
  File "/home/airflow/.local/lib/python3.7/site-packages/airflow/cli/commands/task_command.py", line 107, in _run_task_by_selected_method
    _run_raw_task(args, ti)
  File "/home/airflow/.local/lib/python3.7/site-packages/airflow/cli/commands/task_command.py", line 184, in _run_raw_task
    error_file=args.error_file,
  File "/home/airflow/.local/lib/python3.7/site-packages/airflow/utils/session.py", line 70, in wrapper
    return func(*args, session=session, **kwargs)
  File "/home/airflow/.local/lib/python3.7/site-packages/airflow/models/taskinstance.py", line 1329, in _run_raw_task
    self._execute_task_with_callbacks(context)
  File "/home/airflow/.local/lib/python3.7/site-packages/airflow/models/taskinstance.py", line 1455, in _execute_task_with_callbacks
    result = self._execute_task(context, self.task)
  File "/home/airflow/.local/lib/python3.7/site-packages/airflow/models/taskinstance.py", line 1511, in _execute_task
    result = execute_callable(context=context)
  File "/home/airflow/.local/lib/python3.7/site-packages/airflow/operators/python.py", line 174, in execute
    return_value = self.execute_callable()
  File "/home/airflow/.local/lib/python3.7/site-packages/airflow/operators/python.py", line 185, in execute_callable
    return self.python_callable(*self.op_args, **self.op_kwargs)
  File "/opt/airflow/dags/ingest_fhv.py", line 40, in upload_to_gcs
    blob.upload_from_filename(local_file)
  File "/home/airflow/.local/lib/python3.7/site-packages/google/cloud/storage/blob.py", line 2720, in upload_from_filename
    with open(filename, "rb") as file_obj:
FileNotFoundError: [Errno 2] No such file or directory: '/opt/airflowtaxi+_zone_lookup.parquettaxi+_zone_lookup.parquet'
[2022-02-02 21:47:29,524] {local_task_job.py:154} INFO - Task exited with return code 1
[2022-02-02 21:47:29,676] {local_task_job.py:264} INFO - 0 downstream tasks scheduled from follow-on schedule check
