[2022-01-30 13:11:07,892] {taskinstance.py:1032} INFO - Dependencies all met for <TaskInstance: HomeWorkWeek2.dowdata scheduled__2021-09-02T06:00:00+00:00 [queued]>
[2022-01-30 13:11:07,953] {taskinstance.py:1032} INFO - Dependencies all met for <TaskInstance: HomeWorkWeek2.dowdata scheduled__2021-09-02T06:00:00+00:00 [queued]>
[2022-01-30 13:11:07,954] {taskinstance.py:1238} INFO - 
--------------------------------------------------------------------------------
[2022-01-30 13:11:07,954] {taskinstance.py:1239} INFO - Starting attempt 1 of 2
[2022-01-30 13:11:07,955] {taskinstance.py:1240} INFO - 
--------------------------------------------------------------------------------
[2022-01-30 13:11:07,997] {taskinstance.py:1259} INFO - Executing <Task(BashOperator): dowdata> on 2021-09-02 06:00:00+00:00
[2022-01-30 13:11:08,005] {standard_task_runner.py:52} INFO - Started process 3160 to run task
[2022-01-30 13:11:08,014] {standard_task_runner.py:76} INFO - Running: ['***', 'tasks', 'run', 'HomeWorkWeek2', 'dowdata', 'scheduled__2021-09-02T06:00:00+00:00', '--job-id', '167', '--raw', '--subdir', 'DAGS_FOLDER/dag_questions1.py', '--cfg-path', '/tmp/tmpy95lh8cy', '--error-file', '/tmp/tmpst6tvl13']
[2022-01-30 13:11:08,016] {standard_task_runner.py:77} INFO - Job 167: Subtask dowdata
[2022-01-30 13:11:08,222] {logging_mixin.py:109} INFO - Running <TaskInstance: HomeWorkWeek2.dowdata scheduled__2021-09-02T06:00:00+00:00 [running]> on host 4b3b8c5e49b1
[2022-01-30 13:11:08,399] {warnings.py:110} WARNING - /home/***/.local/lib/python3.7/site-packages/***/utils/context.py:152: AirflowContextDeprecationWarning: Accessing 'execution_date' from the template is deprecated and will be removed in a future version. Please use 'data_interval_start' or 'logical_date' instead.
  warnings.warn(_create_deprecation_warning(key, self._deprecation_replacements[key]))

[2022-01-30 13:11:08,491] {taskinstance.py:1426} INFO - Exporting the following env vars:
AIRFLOW_CTX_DAG_OWNER=***
AIRFLOW_CTX_DAG_ID=HomeWorkWeek2
AIRFLOW_CTX_TASK_ID=dowdata
AIRFLOW_CTX_EXECUTION_DATE=2021-09-02T06:00:00+00:00
AIRFLOW_CTX_DAG_RUN_ID=scheduled__2021-09-02T06:00:00+00:00
[2022-01-30 13:11:08,494] {subprocess.py:62} INFO - Tmp dir root location: 
 /tmp
[2022-01-30 13:11:08,495] {subprocess.py:74} INFO - Running command: ['bash', '-c', 'curl -sSLf https://s3.amazonaws.com/nyc-tlc/trip+data/yellow_tripdata_2021-09.csv > /opt/***output_2021-09.csv']
[2022-01-30 13:11:08,519] {subprocess.py:85} INFO - Output:
[2022-01-30 13:11:09,544] {subprocess.py:89} INFO - curl: (22) The requested URL returned error: 404 Not Found
[2022-01-30 13:11:09,547] {subprocess.py:93} INFO - Command exited with return code 22
[2022-01-30 13:11:09,594] {taskinstance.py:1700} ERROR - Task failed with exception
Traceback (most recent call last):
  File "/home/airflow/.local/lib/python3.7/site-packages/airflow/models/taskinstance.py", line 1329, in _run_raw_task
    self._execute_task_with_callbacks(context)
  File "/home/airflow/.local/lib/python3.7/site-packages/airflow/models/taskinstance.py", line 1455, in _execute_task_with_callbacks
    result = self._execute_task(context, self.task)
  File "/home/airflow/.local/lib/python3.7/site-packages/airflow/models/taskinstance.py", line 1511, in _execute_task
    result = execute_callable(context=context)
  File "/home/airflow/.local/lib/python3.7/site-packages/airflow/operators/bash.py", line 188, in execute
    f'Bash command failed. The command returned a non-zero exit code {result.exit_code}.'
airflow.exceptions.AirflowException: Bash command failed. The command returned a non-zero exit code 22.
[2022-01-30 13:11:09,619] {taskinstance.py:1277} INFO - Marking task as UP_FOR_RETRY. dag_id=HomeWorkWeek2, task_id=dowdata, execution_date=20210902T060000, start_date=20220130T131107, end_date=20220130T131109
[2022-01-30 13:11:09,682] {standard_task_runner.py:92} ERROR - Failed to execute job 167 for task dowdata
Traceback (most recent call last):
  File "/home/airflow/.local/lib/python3.7/site-packages/airflow/task/task_runner/standard_task_runner.py", line 85, in _start_by_fork
    args.func(args, dag=self.dag)
  File "/home/airflow/.local/lib/python3.7/site-packages/airflow/cli/cli_parser.py", line 48, in command
    return func(*args, **kwargs)
  File "/home/airflow/.local/lib/python3.7/site-packages/airflow/utils/cli.py", line 92, in wrapper
    return f(*args, **kwargs)
  File "/home/airflow/.local/lib/python3.7/site-packages/airflow/cli/commands/task_command.py", line 298, in task_run
    _run_task_by_selected_method(args, dag, ti)
  File "/home/airflow/.local/lib/python3.7/site-packages/airflow/cli/commands/task_command.py", line 107, in _run_task_by_selected_method
    _run_raw_task(args, ti)
  File "/home/airflow/.local/lib/python3.7/site-packages/airflow/cli/commands/task_command.py", line 184, in _run_raw_task
    error_file=args.error_file,
  File "/home/airflow/.local/lib/python3.7/site-packages/airflow/utils/session.py", line 70, in wrapper
    return func(*args, session=session, **kwargs)
  File "/home/airflow/.local/lib/python3.7/site-packages/airflow/models/taskinstance.py", line 1329, in _run_raw_task
    self._execute_task_with_callbacks(context)
  File "/home/airflow/.local/lib/python3.7/site-packages/airflow/models/taskinstance.py", line 1455, in _execute_task_with_callbacks
    result = self._execute_task(context, self.task)
  File "/home/airflow/.local/lib/python3.7/site-packages/airflow/models/taskinstance.py", line 1511, in _execute_task
    result = execute_callable(context=context)
  File "/home/airflow/.local/lib/python3.7/site-packages/airflow/operators/bash.py", line 188, in execute
    f'Bash command failed. The command returned a non-zero exit code {result.exit_code}.'
airflow.exceptions.AirflowException: Bash command failed. The command returned a non-zero exit code 22.
[2022-01-30 13:11:09,725] {local_task_job.py:154} INFO - Task exited with return code 1
[2022-01-30 13:11:09,869] {local_task_job.py:264} INFO - 0 downstream tasks scheduled from follow-on schedule check
[2022-01-30 14:59:38,191] {taskinstance.py:1032} INFO - Dependencies all met for <TaskInstance: HomeWorkWeek2.dowdata scheduled__2021-09-02T06:00:00+00:00 [queued]>
[2022-01-30 14:59:38,235] {taskinstance.py:1032} INFO - Dependencies all met for <TaskInstance: HomeWorkWeek2.dowdata scheduled__2021-09-02T06:00:00+00:00 [queued]>
[2022-01-30 14:59:38,235] {taskinstance.py:1238} INFO - 
--------------------------------------------------------------------------------
[2022-01-30 14:59:38,236] {taskinstance.py:1239} INFO - Starting attempt 1 of 2
[2022-01-30 14:59:38,236] {taskinstance.py:1240} INFO - 
--------------------------------------------------------------------------------
[2022-01-30 14:59:38,274] {taskinstance.py:1259} INFO - Executing <Task(BashOperator): dowdata> on 2021-09-02 06:00:00+00:00
[2022-01-30 14:59:38,284] {standard_task_runner.py:52} INFO - Started process 1651 to run task
[2022-01-30 14:59:38,295] {standard_task_runner.py:76} INFO - Running: ['***', 'tasks', 'run', 'HomeWorkWeek2', 'dowdata', 'scheduled__2021-09-02T06:00:00+00:00', '--job-id', '274', '--raw', '--subdir', 'DAGS_FOLDER/dag_questions1.py', '--cfg-path', '/tmp/tmpptiff6fs', '--error-file', '/tmp/tmpgsy671z1']
[2022-01-30 14:59:38,297] {standard_task_runner.py:77} INFO - Job 274: Subtask dowdata
[2022-01-30 14:59:38,502] {logging_mixin.py:109} INFO - Running <TaskInstance: HomeWorkWeek2.dowdata scheduled__2021-09-02T06:00:00+00:00 [running]> on host 785c0c715caa
[2022-01-30 14:59:38,634] {warnings.py:110} WARNING - /home/***/.local/lib/python3.7/site-packages/***/utils/context.py:152: AirflowContextDeprecationWarning: Accessing 'execution_date' from the template is deprecated and will be removed in a future version. Please use 'data_interval_start' or 'logical_date' instead.
  warnings.warn(_create_deprecation_warning(key, self._deprecation_replacements[key]))

[2022-01-30 14:59:38,704] {taskinstance.py:1426} INFO - Exporting the following env vars:
AIRFLOW_CTX_DAG_OWNER=***
AIRFLOW_CTX_DAG_ID=HomeWorkWeek2
AIRFLOW_CTX_TASK_ID=dowdata
AIRFLOW_CTX_EXECUTION_DATE=2021-09-02T06:00:00+00:00
AIRFLOW_CTX_DAG_RUN_ID=scheduled__2021-09-02T06:00:00+00:00
[2022-01-30 14:59:38,710] {subprocess.py:62} INFO - Tmp dir root location: 
 /tmp
[2022-01-30 14:59:38,711] {subprocess.py:74} INFO - Running command: ['bash', '-c', 'curl -sSLf https://s3.amazonaws.com/nyc-tlc/trip+data/yellow_tripdata_2021-09.csv > /opt/***output_2021-09.csv']
[2022-01-30 14:59:38,734] {subprocess.py:85} INFO - Output:
[2022-01-30 14:59:39,805] {subprocess.py:89} INFO - curl: (22) The requested URL returned error: 404 Not Found
[2022-01-30 14:59:39,808] {subprocess.py:93} INFO - Command exited with return code 22
[2022-01-30 14:59:40,011] {taskinstance.py:1700} ERROR - Task failed with exception
Traceback (most recent call last):
  File "/home/airflow/.local/lib/python3.7/site-packages/airflow/models/taskinstance.py", line 1329, in _run_raw_task
    self._execute_task_with_callbacks(context)
  File "/home/airflow/.local/lib/python3.7/site-packages/airflow/models/taskinstance.py", line 1455, in _execute_task_with_callbacks
    result = self._execute_task(context, self.task)
  File "/home/airflow/.local/lib/python3.7/site-packages/airflow/models/taskinstance.py", line 1511, in _execute_task
    result = execute_callable(context=context)
  File "/home/airflow/.local/lib/python3.7/site-packages/airflow/operators/bash.py", line 188, in execute
    f'Bash command failed. The command returned a non-zero exit code {result.exit_code}.'
airflow.exceptions.AirflowException: Bash command failed. The command returned a non-zero exit code 22.
[2022-01-30 14:59:40,039] {taskinstance.py:1277} INFO - Marking task as UP_FOR_RETRY. dag_id=HomeWorkWeek2, task_id=dowdata, execution_date=20210902T060000, start_date=20220130T145938, end_date=20220130T145940
[2022-01-30 14:59:40,110] {standard_task_runner.py:92} ERROR - Failed to execute job 274 for task dowdata
Traceback (most recent call last):
  File "/home/airflow/.local/lib/python3.7/site-packages/airflow/task/task_runner/standard_task_runner.py", line 85, in _start_by_fork
    args.func(args, dag=self.dag)
  File "/home/airflow/.local/lib/python3.7/site-packages/airflow/cli/cli_parser.py", line 48, in command
    return func(*args, **kwargs)
  File "/home/airflow/.local/lib/python3.7/site-packages/airflow/utils/cli.py", line 92, in wrapper
    return f(*args, **kwargs)
  File "/home/airflow/.local/lib/python3.7/site-packages/airflow/cli/commands/task_command.py", line 298, in task_run
    _run_task_by_selected_method(args, dag, ti)
  File "/home/airflow/.local/lib/python3.7/site-packages/airflow/cli/commands/task_command.py", line 107, in _run_task_by_selected_method
    _run_raw_task(args, ti)
  File "/home/airflow/.local/lib/python3.7/site-packages/airflow/cli/commands/task_command.py", line 184, in _run_raw_task
    error_file=args.error_file,
  File "/home/airflow/.local/lib/python3.7/site-packages/airflow/utils/session.py", line 70, in wrapper
    return func(*args, session=session, **kwargs)
  File "/home/airflow/.local/lib/python3.7/site-packages/airflow/models/taskinstance.py", line 1329, in _run_raw_task
    self._execute_task_with_callbacks(context)
  File "/home/airflow/.local/lib/python3.7/site-packages/airflow/models/taskinstance.py", line 1455, in _execute_task_with_callbacks
    result = self._execute_task(context, self.task)
  File "/home/airflow/.local/lib/python3.7/site-packages/airflow/models/taskinstance.py", line 1511, in _execute_task
    result = execute_callable(context=context)
  File "/home/airflow/.local/lib/python3.7/site-packages/airflow/operators/bash.py", line 188, in execute
    f'Bash command failed. The command returned a non-zero exit code {result.exit_code}.'
airflow.exceptions.AirflowException: Bash command failed. The command returned a non-zero exit code 22.
[2022-01-30 14:59:40,135] {local_task_job.py:154} INFO - Task exited with return code 1
[2022-01-30 14:59:40,283] {local_task_job.py:264} INFO - 0 downstream tasks scheduled from follow-on schedule check
