[2022-01-30 13:16:11,340] {taskinstance.py:1032} INFO - Dependencies all met for <TaskInstance: HomeWorkWeek2.dowdata scheduled__2021-09-02T06:00:00+00:00 [queued]>
[2022-01-30 13:16:11,383] {taskinstance.py:1032} INFO - Dependencies all met for <TaskInstance: HomeWorkWeek2.dowdata scheduled__2021-09-02T06:00:00+00:00 [queued]>
[2022-01-30 13:16:11,383] {taskinstance.py:1238} INFO - 
--------------------------------------------------------------------------------
[2022-01-30 13:16:11,384] {taskinstance.py:1239} INFO - Starting attempt 2 of 2
[2022-01-30 13:16:11,384] {taskinstance.py:1240} INFO - 
--------------------------------------------------------------------------------
[2022-01-30 13:16:11,424] {taskinstance.py:1259} INFO - Executing <Task(BashOperator): dowdata> on 2021-09-02 06:00:00+00:00
[2022-01-30 13:16:11,433] {standard_task_runner.py:52} INFO - Started process 3403 to run task
[2022-01-30 13:16:11,441] {standard_task_runner.py:76} INFO - Running: ['***', 'tasks', 'run', 'HomeWorkWeek2', 'dowdata', 'scheduled__2021-09-02T06:00:00+00:00', '--job-id', '172', '--raw', '--subdir', 'DAGS_FOLDER/dag_questions1.py', '--cfg-path', '/tmp/tmp70ehq9v7', '--error-file', '/tmp/tmpvdr3nvn9']
[2022-01-30 13:16:11,443] {standard_task_runner.py:77} INFO - Job 172: Subtask dowdata
[2022-01-30 13:16:11,634] {logging_mixin.py:109} INFO - Running <TaskInstance: HomeWorkWeek2.dowdata scheduled__2021-09-02T06:00:00+00:00 [running]> on host 4b3b8c5e49b1
[2022-01-30 13:16:11,784] {warnings.py:110} WARNING - /home/***/.local/lib/python3.7/site-packages/***/utils/context.py:152: AirflowContextDeprecationWarning: Accessing 'execution_date' from the template is deprecated and will be removed in a future version. Please use 'data_interval_start' or 'logical_date' instead.
  warnings.warn(_create_deprecation_warning(key, self._deprecation_replacements[key]))

[2022-01-30 13:16:11,842] {taskinstance.py:1426} INFO - Exporting the following env vars:
AIRFLOW_CTX_DAG_OWNER=***
AIRFLOW_CTX_DAG_ID=HomeWorkWeek2
AIRFLOW_CTX_TASK_ID=dowdata
AIRFLOW_CTX_EXECUTION_DATE=2021-09-02T06:00:00+00:00
AIRFLOW_CTX_DAG_RUN_ID=scheduled__2021-09-02T06:00:00+00:00
[2022-01-30 13:16:11,845] {subprocess.py:62} INFO - Tmp dir root location: 
 /tmp
[2022-01-30 13:16:11,847] {subprocess.py:74} INFO - Running command: ['bash', '-c', 'curl -sSLf https://s3.amazonaws.com/nyc-tlc/trip+data/yellow_tripdata_2021-09.csv > /opt/***output_2021-09.csv']
[2022-01-30 13:16:11,877] {subprocess.py:85} INFO - Output:
[2022-01-30 13:16:13,152] {subprocess.py:89} INFO - curl: (22) The requested URL returned error: 404 Not Found
[2022-01-30 13:16:13,153] {subprocess.py:93} INFO - Command exited with return code 22
[2022-01-30 13:16:13,200] {taskinstance.py:1700} ERROR - Task failed with exception
Traceback (most recent call last):
  File "/home/airflow/.local/lib/python3.7/site-packages/airflow/models/taskinstance.py", line 1329, in _run_raw_task
    self._execute_task_with_callbacks(context)
  File "/home/airflow/.local/lib/python3.7/site-packages/airflow/models/taskinstance.py", line 1455, in _execute_task_with_callbacks
    result = self._execute_task(context, self.task)
  File "/home/airflow/.local/lib/python3.7/site-packages/airflow/models/taskinstance.py", line 1511, in _execute_task
    result = execute_callable(context=context)
  File "/home/airflow/.local/lib/python3.7/site-packages/airflow/operators/bash.py", line 188, in execute
    f'Bash command failed. The command returned a non-zero exit code {result.exit_code}.'
airflow.exceptions.AirflowException: Bash command failed. The command returned a non-zero exit code 22.
[2022-01-30 13:16:13,230] {taskinstance.py:1277} INFO - Marking task as FAILED. dag_id=HomeWorkWeek2, task_id=dowdata, execution_date=20210902T060000, start_date=20220130T131611, end_date=20220130T131613
[2022-01-30 13:16:13,286] {standard_task_runner.py:92} ERROR - Failed to execute job 172 for task dowdata
Traceback (most recent call last):
  File "/home/airflow/.local/lib/python3.7/site-packages/airflow/task/task_runner/standard_task_runner.py", line 85, in _start_by_fork
    args.func(args, dag=self.dag)
  File "/home/airflow/.local/lib/python3.7/site-packages/airflow/cli/cli_parser.py", line 48, in command
    return func(*args, **kwargs)
  File "/home/airflow/.local/lib/python3.7/site-packages/airflow/utils/cli.py", line 92, in wrapper
    return f(*args, **kwargs)
  File "/home/airflow/.local/lib/python3.7/site-packages/airflow/cli/commands/task_command.py", line 298, in task_run
    _run_task_by_selected_method(args, dag, ti)
  File "/home/airflow/.local/lib/python3.7/site-packages/airflow/cli/commands/task_command.py", line 107, in _run_task_by_selected_method
    _run_raw_task(args, ti)
  File "/home/airflow/.local/lib/python3.7/site-packages/airflow/cli/commands/task_command.py", line 184, in _run_raw_task
    error_file=args.error_file,
  File "/home/airflow/.local/lib/python3.7/site-packages/airflow/utils/session.py", line 70, in wrapper
    return func(*args, session=session, **kwargs)
  File "/home/airflow/.local/lib/python3.7/site-packages/airflow/models/taskinstance.py", line 1329, in _run_raw_task
    self._execute_task_with_callbacks(context)
  File "/home/airflow/.local/lib/python3.7/site-packages/airflow/models/taskinstance.py", line 1455, in _execute_task_with_callbacks
    result = self._execute_task(context, self.task)
  File "/home/airflow/.local/lib/python3.7/site-packages/airflow/models/taskinstance.py", line 1511, in _execute_task
    result = execute_callable(context=context)
  File "/home/airflow/.local/lib/python3.7/site-packages/airflow/operators/bash.py", line 188, in execute
    f'Bash command failed. The command returned a non-zero exit code {result.exit_code}.'
airflow.exceptions.AirflowException: Bash command failed. The command returned a non-zero exit code 22.
[2022-01-30 13:16:13,349] {local_task_job.py:154} INFO - Task exited with return code 1
[2022-01-30 13:16:13,513] {local_task_job.py:264} INFO - 0 downstream tasks scheduled from follow-on schedule check
[2022-01-30 15:04:42,047] {taskinstance.py:1032} INFO - Dependencies all met for <TaskInstance: HomeWorkWeek2.dowdata scheduled__2021-09-02T06:00:00+00:00 [queued]>
[2022-01-30 15:04:42,103] {taskinstance.py:1032} INFO - Dependencies all met for <TaskInstance: HomeWorkWeek2.dowdata scheduled__2021-09-02T06:00:00+00:00 [queued]>
[2022-01-30 15:04:42,104] {taskinstance.py:1238} INFO - 
--------------------------------------------------------------------------------
[2022-01-30 15:04:42,105] {taskinstance.py:1239} INFO - Starting attempt 2 of 2
[2022-01-30 15:04:42,105] {taskinstance.py:1240} INFO - 
--------------------------------------------------------------------------------
[2022-01-30 15:04:42,148] {taskinstance.py:1259} INFO - Executing <Task(BashOperator): dowdata> on 2021-09-02 06:00:00+00:00
[2022-01-30 15:04:42,155] {standard_task_runner.py:52} INFO - Started process 1894 to run task
[2022-01-30 15:04:42,162] {standard_task_runner.py:76} INFO - Running: ['***', 'tasks', 'run', 'HomeWorkWeek2', 'dowdata', 'scheduled__2021-09-02T06:00:00+00:00', '--job-id', '279', '--raw', '--subdir', 'DAGS_FOLDER/dag_questions1.py', '--cfg-path', '/tmp/tmpalamik6n', '--error-file', '/tmp/tmpn57ipijw']
[2022-01-30 15:04:42,164] {standard_task_runner.py:77} INFO - Job 279: Subtask dowdata
[2022-01-30 15:04:42,338] {logging_mixin.py:109} INFO - Running <TaskInstance: HomeWorkWeek2.dowdata scheduled__2021-09-02T06:00:00+00:00 [running]> on host 785c0c715caa
[2022-01-30 15:04:42,466] {warnings.py:110} WARNING - /home/***/.local/lib/python3.7/site-packages/***/utils/context.py:152: AirflowContextDeprecationWarning: Accessing 'execution_date' from the template is deprecated and will be removed in a future version. Please use 'data_interval_start' or 'logical_date' instead.
  warnings.warn(_create_deprecation_warning(key, self._deprecation_replacements[key]))

[2022-01-30 15:04:42,519] {taskinstance.py:1426} INFO - Exporting the following env vars:
AIRFLOW_CTX_DAG_OWNER=***
AIRFLOW_CTX_DAG_ID=HomeWorkWeek2
AIRFLOW_CTX_TASK_ID=dowdata
AIRFLOW_CTX_EXECUTION_DATE=2021-09-02T06:00:00+00:00
AIRFLOW_CTX_DAG_RUN_ID=scheduled__2021-09-02T06:00:00+00:00
[2022-01-30 15:04:42,522] {subprocess.py:62} INFO - Tmp dir root location: 
 /tmp
[2022-01-30 15:04:42,523] {subprocess.py:74} INFO - Running command: ['bash', '-c', 'curl -sSLf https://s3.amazonaws.com/nyc-tlc/trip+data/yellow_tripdata_2021-09.csv > /opt/***output_2021-09.csv']
[2022-01-30 15:04:42,543] {subprocess.py:85} INFO - Output:
[2022-01-30 15:04:43,625] {subprocess.py:89} INFO - curl: (22) The requested URL returned error: 404 Not Found
[2022-01-30 15:04:43,629] {subprocess.py:93} INFO - Command exited with return code 22
[2022-01-30 15:04:43,679] {taskinstance.py:1700} ERROR - Task failed with exception
Traceback (most recent call last):
  File "/home/airflow/.local/lib/python3.7/site-packages/airflow/models/taskinstance.py", line 1329, in _run_raw_task
    self._execute_task_with_callbacks(context)
  File "/home/airflow/.local/lib/python3.7/site-packages/airflow/models/taskinstance.py", line 1455, in _execute_task_with_callbacks
    result = self._execute_task(context, self.task)
  File "/home/airflow/.local/lib/python3.7/site-packages/airflow/models/taskinstance.py", line 1511, in _execute_task
    result = execute_callable(context=context)
  File "/home/airflow/.local/lib/python3.7/site-packages/airflow/operators/bash.py", line 188, in execute
    f'Bash command failed. The command returned a non-zero exit code {result.exit_code}.'
airflow.exceptions.AirflowException: Bash command failed. The command returned a non-zero exit code 22.
[2022-01-30 15:04:43,705] {taskinstance.py:1277} INFO - Marking task as FAILED. dag_id=HomeWorkWeek2, task_id=dowdata, execution_date=20210902T060000, start_date=20220130T150442, end_date=20220130T150443
[2022-01-30 15:04:43,753] {standard_task_runner.py:92} ERROR - Failed to execute job 279 for task dowdata
Traceback (most recent call last):
  File "/home/airflow/.local/lib/python3.7/site-packages/airflow/task/task_runner/standard_task_runner.py", line 85, in _start_by_fork
    args.func(args, dag=self.dag)
  File "/home/airflow/.local/lib/python3.7/site-packages/airflow/cli/cli_parser.py", line 48, in command
    return func(*args, **kwargs)
  File "/home/airflow/.local/lib/python3.7/site-packages/airflow/utils/cli.py", line 92, in wrapper
    return f(*args, **kwargs)
  File "/home/airflow/.local/lib/python3.7/site-packages/airflow/cli/commands/task_command.py", line 298, in task_run
    _run_task_by_selected_method(args, dag, ti)
  File "/home/airflow/.local/lib/python3.7/site-packages/airflow/cli/commands/task_command.py", line 107, in _run_task_by_selected_method
    _run_raw_task(args, ti)
  File "/home/airflow/.local/lib/python3.7/site-packages/airflow/cli/commands/task_command.py", line 184, in _run_raw_task
    error_file=args.error_file,
  File "/home/airflow/.local/lib/python3.7/site-packages/airflow/utils/session.py", line 70, in wrapper
    return func(*args, session=session, **kwargs)
  File "/home/airflow/.local/lib/python3.7/site-packages/airflow/models/taskinstance.py", line 1329, in _run_raw_task
    self._execute_task_with_callbacks(context)
  File "/home/airflow/.local/lib/python3.7/site-packages/airflow/models/taskinstance.py", line 1455, in _execute_task_with_callbacks
    result = self._execute_task(context, self.task)
  File "/home/airflow/.local/lib/python3.7/site-packages/airflow/models/taskinstance.py", line 1511, in _execute_task
    result = execute_callable(context=context)
  File "/home/airflow/.local/lib/python3.7/site-packages/airflow/operators/bash.py", line 188, in execute
    f'Bash command failed. The command returned a non-zero exit code {result.exit_code}.'
airflow.exceptions.AirflowException: Bash command failed. The command returned a non-zero exit code 22.
[2022-01-30 15:04:43,772] {local_task_job.py:154} INFO - Task exited with return code 1
[2022-01-30 15:04:43,909] {local_task_job.py:264} INFO - 0 downstream tasks scheduled from follow-on schedule check
