[2022-01-29 14:08:17,513] {taskinstance.py:1032} INFO - Dependencies all met for <TaskInstance: HomeWorkWeek2.get_data scheduled__2021-12-02T06:00:00+00:00 [queued]>
[2022-01-29 14:08:17,548] {taskinstance.py:1032} INFO - Dependencies all met for <TaskInstance: HomeWorkWeek2.get_data scheduled__2021-12-02T06:00:00+00:00 [queued]>
[2022-01-29 14:08:17,548] {taskinstance.py:1238} INFO - 
--------------------------------------------------------------------------------
[2022-01-29 14:08:17,548] {taskinstance.py:1239} INFO - Starting attempt 1 of 1
[2022-01-29 14:08:17,548] {taskinstance.py:1240} INFO - 
--------------------------------------------------------------------------------
[2022-01-29 14:08:17,600] {taskinstance.py:1259} INFO - Executing <Task(BashOperator): get_data> on 2021-12-02 06:00:00+00:00
[2022-01-29 14:08:17,606] {standard_task_runner.py:52} INFO - Started process 441 to run task
[2022-01-29 14:08:17,614] {standard_task_runner.py:76} INFO - Running: ['***', 'tasks', 'run', 'HomeWorkWeek2', 'get_data', 'scheduled__2021-12-02T06:00:00+00:00', '--job-id', '53', '--raw', '--subdir', 'DAGS_FOLDER/dag_questions1.py', '--cfg-path', '/tmp/tmpl6pv08s9', '--error-file', '/tmp/tmpbrdzkkmv']
[2022-01-29 14:08:17,614] {standard_task_runner.py:77} INFO - Job 53: Subtask get_data
[2022-01-29 14:08:17,775] {logging_mixin.py:109} INFO - Running <TaskInstance: HomeWorkWeek2.get_data scheduled__2021-12-02T06:00:00+00:00 [running]> on host d1e1fe005577
[2022-01-29 14:08:17,985] {taskinstance.py:1426} INFO - Exporting the following env vars:
AIRFLOW_CTX_DAG_OWNER=***
AIRFLOW_CTX_DAG_ID=HomeWorkWeek2
AIRFLOW_CTX_TASK_ID=get_data
AIRFLOW_CTX_EXECUTION_DATE=2021-12-02T06:00:00+00:00
AIRFLOW_CTX_DAG_RUN_ID=scheduled__2021-12-02T06:00:00+00:00
[2022-01-29 14:08:17,987] {subprocess.py:62} INFO - Tmp dir root location: 
 /tmp
[2022-01-29 14:08:17,989] {subprocess.py:74} INFO - Running command: ['bash', '-c', 'echo "helloworld!!"']
[2022-01-29 14:08:18,003] {subprocess.py:85} INFO - Output:
[2022-01-29 14:08:18,006] {subprocess.py:89} INFO - helloworld!!
[2022-01-29 14:08:18,006] {subprocess.py:93} INFO - Command exited with return code 0
[2022-01-29 14:08:18,073] {taskinstance.py:1277} INFO - Marking task as SUCCESS. dag_id=HomeWorkWeek2, task_id=get_data, execution_date=20211202T060000, start_date=20220129T140817, end_date=20220129T140818
[2022-01-29 14:08:18,124] {local_task_job.py:154} INFO - Task exited with return code 0
[2022-01-29 14:08:18,239] {local_task_job.py:264} INFO - 0 downstream tasks scheduled from follow-on schedule check
[2022-01-30 10:55:49,453] {taskinstance.py:1032} INFO - Dependencies all met for <TaskInstance: HomeWorkWeek2.get_data scheduled__2021-12-02T06:00:00+00:00 [queued]>
[2022-01-30 10:55:49,499] {taskinstance.py:1032} INFO - Dependencies all met for <TaskInstance: HomeWorkWeek2.get_data scheduled__2021-12-02T06:00:00+00:00 [queued]>
[2022-01-30 10:55:49,499] {taskinstance.py:1238} INFO - 
--------------------------------------------------------------------------------
[2022-01-30 10:55:49,499] {taskinstance.py:1239} INFO - Starting attempt 1 of 1
[2022-01-30 10:55:49,500] {taskinstance.py:1240} INFO - 
--------------------------------------------------------------------------------
[2022-01-30 10:55:49,541] {taskinstance.py:1259} INFO - Executing <Task(BashOperator): get_data> on 2021-12-02 06:00:00+00:00
[2022-01-30 10:55:49,548] {standard_task_runner.py:52} INFO - Started process 1225 to run task
[2022-01-30 10:55:49,554] {standard_task_runner.py:76} INFO - Running: ['***', 'tasks', 'run', 'HomeWorkWeek2', 'get_data', 'scheduled__2021-12-02T06:00:00+00:00', '--job-id', '98', '--raw', '--subdir', 'DAGS_FOLDER/dag_questions1.py', '--cfg-path', '/tmp/tmpnud4el8a', '--error-file', '/tmp/tmpcg52tqta']
[2022-01-30 10:55:49,555] {standard_task_runner.py:77} INFO - Job 98: Subtask get_data
[2022-01-30 10:55:49,717] {logging_mixin.py:109} INFO - Running <TaskInstance: HomeWorkWeek2.get_data scheduled__2021-12-02T06:00:00+00:00 [running]> on host fc414ca9b482
[2022-01-30 10:55:49,878] {warnings.py:110} WARNING - /home/***/.local/lib/python3.7/site-packages/***/utils/context.py:152: AirflowContextDeprecationWarning: Accessing 'execution_date' from the template is deprecated and will be removed in a future version. Please use 'data_interval_start' or 'logical_date' instead.
  warnings.warn(_create_deprecation_warning(key, self._deprecation_replacements[key]))

[2022-01-30 10:55:49,960] {taskinstance.py:1426} INFO - Exporting the following env vars:
AIRFLOW_CTX_DAG_OWNER=***
AIRFLOW_CTX_DAG_ID=HomeWorkWeek2
AIRFLOW_CTX_TASK_ID=get_data
AIRFLOW_CTX_EXECUTION_DATE=2021-12-02T06:00:00+00:00
AIRFLOW_CTX_DAG_RUN_ID=scheduled__2021-12-02T06:00:00+00:00
[2022-01-30 10:55:49,962] {subprocess.py:62} INFO - Tmp dir root location: 
 /tmp
[2022-01-30 10:55:49,963] {subprocess.py:74} INFO - Running command: ['bash', '-c', 'curl -sSLf https://s3.amazonaws.com/nyc-tlc/trip+data/yellow_tripdata_2021-12.csv > /opt/***output_2021-12.csv']
[2022-01-30 10:55:49,981] {subprocess.py:85} INFO - Output:
[2022-01-30 10:55:51,019] {subprocess.py:89} INFO - curl: (22) The requested URL returned error: 404 Not Found
[2022-01-30 10:55:51,022] {subprocess.py:93} INFO - Command exited with return code 22
[2022-01-30 10:55:51,060] {taskinstance.py:1700} ERROR - Task failed with exception
Traceback (most recent call last):
  File "/home/airflow/.local/lib/python3.7/site-packages/airflow/models/taskinstance.py", line 1329, in _run_raw_task
    self._execute_task_with_callbacks(context)
  File "/home/airflow/.local/lib/python3.7/site-packages/airflow/models/taskinstance.py", line 1455, in _execute_task_with_callbacks
    result = self._execute_task(context, self.task)
  File "/home/airflow/.local/lib/python3.7/site-packages/airflow/models/taskinstance.py", line 1511, in _execute_task
    result = execute_callable(context=context)
  File "/home/airflow/.local/lib/python3.7/site-packages/airflow/operators/bash.py", line 188, in execute
    f'Bash command failed. The command returned a non-zero exit code {result.exit_code}.'
airflow.exceptions.AirflowException: Bash command failed. The command returned a non-zero exit code 22.
[2022-01-30 10:55:51,088] {taskinstance.py:1277} INFO - Marking task as FAILED. dag_id=HomeWorkWeek2, task_id=get_data, execution_date=20211202T060000, start_date=20220130T105549, end_date=20220130T105551
[2022-01-30 10:55:51,137] {standard_task_runner.py:92} ERROR - Failed to execute job 98 for task get_data
Traceback (most recent call last):
  File "/home/airflow/.local/lib/python3.7/site-packages/airflow/task/task_runner/standard_task_runner.py", line 85, in _start_by_fork
    args.func(args, dag=self.dag)
  File "/home/airflow/.local/lib/python3.7/site-packages/airflow/cli/cli_parser.py", line 48, in command
    return func(*args, **kwargs)
  File "/home/airflow/.local/lib/python3.7/site-packages/airflow/utils/cli.py", line 92, in wrapper
    return f(*args, **kwargs)
  File "/home/airflow/.local/lib/python3.7/site-packages/airflow/cli/commands/task_command.py", line 298, in task_run
    _run_task_by_selected_method(args, dag, ti)
  File "/home/airflow/.local/lib/python3.7/site-packages/airflow/cli/commands/task_command.py", line 107, in _run_task_by_selected_method
    _run_raw_task(args, ti)
  File "/home/airflow/.local/lib/python3.7/site-packages/airflow/cli/commands/task_command.py", line 184, in _run_raw_task
    error_file=args.error_file,
  File "/home/airflow/.local/lib/python3.7/site-packages/airflow/utils/session.py", line 70, in wrapper
    return func(*args, session=session, **kwargs)
  File "/home/airflow/.local/lib/python3.7/site-packages/airflow/models/taskinstance.py", line 1329, in _run_raw_task
    self._execute_task_with_callbacks(context)
  File "/home/airflow/.local/lib/python3.7/site-packages/airflow/models/taskinstance.py", line 1455, in _execute_task_with_callbacks
    result = self._execute_task(context, self.task)
  File "/home/airflow/.local/lib/python3.7/site-packages/airflow/models/taskinstance.py", line 1511, in _execute_task
    result = execute_callable(context=context)
  File "/home/airflow/.local/lib/python3.7/site-packages/airflow/operators/bash.py", line 188, in execute
    f'Bash command failed. The command returned a non-zero exit code {result.exit_code}.'
airflow.exceptions.AirflowException: Bash command failed. The command returned a non-zero exit code 22.
[2022-01-30 10:55:51,161] {local_task_job.py:154} INFO - Task exited with return code 1
[2022-01-30 10:55:51,260] {local_task_job.py:264} INFO - 0 downstream tasks scheduled from follow-on schedule check
