[2022-01-29 14:08:11,916] {taskinstance.py:1032} INFO - Dependencies all met for <TaskInstance: HomeWorkWeek2.get_data scheduled__2021-08-02T06:00:00+00:00 [queued]>
[2022-01-29 14:08:11,972] {taskinstance.py:1032} INFO - Dependencies all met for <TaskInstance: HomeWorkWeek2.get_data scheduled__2021-08-02T06:00:00+00:00 [queued]>
[2022-01-29 14:08:11,972] {taskinstance.py:1238} INFO - 
--------------------------------------------------------------------------------
[2022-01-29 14:08:11,972] {taskinstance.py:1239} INFO - Starting attempt 1 of 1
[2022-01-29 14:08:11,972] {taskinstance.py:1240} INFO - 
--------------------------------------------------------------------------------
[2022-01-29 14:08:12,036] {taskinstance.py:1259} INFO - Executing <Task(BashOperator): get_data> on 2021-08-02 06:00:00+00:00
[2022-01-29 14:08:12,053] {standard_task_runner.py:52} INFO - Started process 430 to run task
[2022-01-29 14:08:12,062] {standard_task_runner.py:76} INFO - Running: ['***', 'tasks', 'run', 'HomeWorkWeek2', 'get_data', 'scheduled__2021-08-02T06:00:00+00:00', '--job-id', '49', '--raw', '--subdir', 'DAGS_FOLDER/dag_questions1.py', '--cfg-path', '/tmp/tmp386t_4qm', '--error-file', '/tmp/tmp7hvif15a']
[2022-01-29 14:08:12,063] {standard_task_runner.py:77} INFO - Job 49: Subtask get_data
[2022-01-29 14:08:12,298] {logging_mixin.py:109} INFO - Running <TaskInstance: HomeWorkWeek2.get_data scheduled__2021-08-02T06:00:00+00:00 [running]> on host d1e1fe005577
[2022-01-29 14:08:12,506] {taskinstance.py:1426} INFO - Exporting the following env vars:
AIRFLOW_CTX_DAG_OWNER=***
AIRFLOW_CTX_DAG_ID=HomeWorkWeek2
AIRFLOW_CTX_TASK_ID=get_data
AIRFLOW_CTX_EXECUTION_DATE=2021-08-02T06:00:00+00:00
AIRFLOW_CTX_DAG_RUN_ID=scheduled__2021-08-02T06:00:00+00:00
[2022-01-29 14:08:12,509] {subprocess.py:62} INFO - Tmp dir root location: 
 /tmp
[2022-01-29 14:08:12,510] {subprocess.py:74} INFO - Running command: ['bash', '-c', 'echo "helloworld!!"']
[2022-01-29 14:08:12,529] {subprocess.py:85} INFO - Output:
[2022-01-29 14:08:12,530] {subprocess.py:89} INFO - helloworld!!
[2022-01-29 14:08:12,530] {subprocess.py:93} INFO - Command exited with return code 0
[2022-01-29 14:08:12,665] {taskinstance.py:1277} INFO - Marking task as SUCCESS. dag_id=HomeWorkWeek2, task_id=get_data, execution_date=20210802T060000, start_date=20220129T140811, end_date=20220129T140812
[2022-01-29 14:08:12,781] {local_task_job.py:154} INFO - Task exited with return code 0
[2022-01-29 14:08:12,902] {local_task_job.py:264} INFO - 0 downstream tasks scheduled from follow-on schedule check
[2022-01-30 10:55:19,028] {taskinstance.py:1032} INFO - Dependencies all met for <TaskInstance: HomeWorkWeek2.get_data scheduled__2021-08-02T06:00:00+00:00 [queued]>
[2022-01-30 10:55:19,091] {taskinstance.py:1032} INFO - Dependencies all met for <TaskInstance: HomeWorkWeek2.get_data scheduled__2021-08-02T06:00:00+00:00 [queued]>
[2022-01-30 10:55:19,093] {taskinstance.py:1238} INFO - 
--------------------------------------------------------------------------------
[2022-01-30 10:55:19,093] {taskinstance.py:1239} INFO - Starting attempt 1 of 1
[2022-01-30 10:55:19,094] {taskinstance.py:1240} INFO - 
--------------------------------------------------------------------------------
[2022-01-30 10:55:19,158] {taskinstance.py:1259} INFO - Executing <Task(BashOperator): get_data> on 2021-08-02 06:00:00+00:00
[2022-01-30 10:55:19,180] {standard_task_runner.py:76} INFO - Running: ['***', 'tasks', 'run', 'HomeWorkWeek2', 'get_data', 'scheduled__2021-08-02T06:00:00+00:00', '--job-id', '94', '--raw', '--subdir', 'DAGS_FOLDER/dag_questions1.py', '--cfg-path', '/tmp/tmpgyz0z1ye', '--error-file', '/tmp/tmpiz5drgub']
[2022-01-30 10:55:19,173] {standard_task_runner.py:52} INFO - Started process 1185 to run task
[2022-01-30 10:55:19,181] {standard_task_runner.py:77} INFO - Job 94: Subtask get_data
[2022-01-30 10:55:19,572] {logging_mixin.py:109} INFO - Running <TaskInstance: HomeWorkWeek2.get_data scheduled__2021-08-02T06:00:00+00:00 [running]> on host fc414ca9b482
[2022-01-30 10:55:19,771] {warnings.py:110} WARNING - /home/***/.local/lib/python3.7/site-packages/***/utils/context.py:152: AirflowContextDeprecationWarning: Accessing 'execution_date' from the template is deprecated and will be removed in a future version. Please use 'data_interval_start' or 'logical_date' instead.
  warnings.warn(_create_deprecation_warning(key, self._deprecation_replacements[key]))

[2022-01-30 10:55:19,904] {taskinstance.py:1426} INFO - Exporting the following env vars:
AIRFLOW_CTX_DAG_OWNER=***
AIRFLOW_CTX_DAG_ID=HomeWorkWeek2
AIRFLOW_CTX_TASK_ID=get_data
AIRFLOW_CTX_EXECUTION_DATE=2021-08-02T06:00:00+00:00
AIRFLOW_CTX_DAG_RUN_ID=scheduled__2021-08-02T06:00:00+00:00
[2022-01-30 10:55:19,907] {subprocess.py:62} INFO - Tmp dir root location: 
 /tmp
[2022-01-30 10:55:19,908] {subprocess.py:74} INFO - Running command: ['bash', '-c', 'curl -sSLf https://s3.amazonaws.com/nyc-tlc/trip+data/yellow_tripdata_2021-08.csv > /opt/***output_2021-08.csv']
[2022-01-30 10:55:19,939] {subprocess.py:85} INFO - Output:
[2022-01-30 10:55:21,003] {subprocess.py:89} INFO - curl: (22) The requested URL returned error: 404 Not Found
[2022-01-30 10:55:21,007] {subprocess.py:93} INFO - Command exited with return code 22
[2022-01-30 10:55:21,276] {taskinstance.py:1700} ERROR - Task failed with exception
Traceback (most recent call last):
  File "/home/airflow/.local/lib/python3.7/site-packages/airflow/models/taskinstance.py", line 1329, in _run_raw_task
    self._execute_task_with_callbacks(context)
  File "/home/airflow/.local/lib/python3.7/site-packages/airflow/models/taskinstance.py", line 1455, in _execute_task_with_callbacks
    result = self._execute_task(context, self.task)
  File "/home/airflow/.local/lib/python3.7/site-packages/airflow/models/taskinstance.py", line 1511, in _execute_task
    result = execute_callable(context=context)
  File "/home/airflow/.local/lib/python3.7/site-packages/airflow/operators/bash.py", line 188, in execute
    f'Bash command failed. The command returned a non-zero exit code {result.exit_code}.'
airflow.exceptions.AirflowException: Bash command failed. The command returned a non-zero exit code 22.
[2022-01-30 10:55:21,325] {taskinstance.py:1277} INFO - Marking task as FAILED. dag_id=HomeWorkWeek2, task_id=get_data, execution_date=20210802T060000, start_date=20220130T105519, end_date=20220130T105521
[2022-01-30 10:55:21,383] {standard_task_runner.py:92} ERROR - Failed to execute job 94 for task get_data
Traceback (most recent call last):
  File "/home/airflow/.local/lib/python3.7/site-packages/airflow/task/task_runner/standard_task_runner.py", line 85, in _start_by_fork
    args.func(args, dag=self.dag)
  File "/home/airflow/.local/lib/python3.7/site-packages/airflow/cli/cli_parser.py", line 48, in command
    return func(*args, **kwargs)
  File "/home/airflow/.local/lib/python3.7/site-packages/airflow/utils/cli.py", line 92, in wrapper
    return f(*args, **kwargs)
  File "/home/airflow/.local/lib/python3.7/site-packages/airflow/cli/commands/task_command.py", line 298, in task_run
    _run_task_by_selected_method(args, dag, ti)
  File "/home/airflow/.local/lib/python3.7/site-packages/airflow/cli/commands/task_command.py", line 107, in _run_task_by_selected_method
    _run_raw_task(args, ti)
  File "/home/airflow/.local/lib/python3.7/site-packages/airflow/cli/commands/task_command.py", line 184, in _run_raw_task
    error_file=args.error_file,
  File "/home/airflow/.local/lib/python3.7/site-packages/airflow/utils/session.py", line 70, in wrapper
    return func(*args, session=session, **kwargs)
  File "/home/airflow/.local/lib/python3.7/site-packages/airflow/models/taskinstance.py", line 1329, in _run_raw_task
    self._execute_task_with_callbacks(context)
  File "/home/airflow/.local/lib/python3.7/site-packages/airflow/models/taskinstance.py", line 1455, in _execute_task_with_callbacks
    result = self._execute_task(context, self.task)
  File "/home/airflow/.local/lib/python3.7/site-packages/airflow/models/taskinstance.py", line 1511, in _execute_task
    result = execute_callable(context=context)
  File "/home/airflow/.local/lib/python3.7/site-packages/airflow/operators/bash.py", line 188, in execute
    f'Bash command failed. The command returned a non-zero exit code {result.exit_code}.'
airflow.exceptions.AirflowException: Bash command failed. The command returned a non-zero exit code 22.
[2022-01-30 10:55:21,425] {local_task_job.py:154} INFO - Task exited with return code 1
[2022-01-30 10:55:21,517] {local_task_job.py:264} INFO - 0 downstream tasks scheduled from follow-on schedule check
