[2022-02-02 21:02:26,806] {taskinstance.py:1032} INFO - Dependencies all met for <TaskInstance: HomeWorkWeek2.csv_to_parquet scheduled__2019-04-02T06:00:00+00:00 [queued]>
[2022-02-02 21:02:26,863] {taskinstance.py:1032} INFO - Dependencies all met for <TaskInstance: HomeWorkWeek2.csv_to_parquet scheduled__2019-04-02T06:00:00+00:00 [queued]>
[2022-02-02 21:02:26,863] {taskinstance.py:1238} INFO - 
--------------------------------------------------------------------------------
[2022-02-02 21:02:26,863] {taskinstance.py:1239} INFO - Starting attempt 2 of 2
[2022-02-02 21:02:26,863] {taskinstance.py:1240} INFO - 
--------------------------------------------------------------------------------
[2022-02-02 21:02:26,930] {taskinstance.py:1259} INFO - Executing <Task(PythonOperator): csv_to_parquet> on 2019-04-02 06:00:00+00:00
[2022-02-02 21:02:26,938] {standard_task_runner.py:52} INFO - Started process 91 to run task
[2022-02-02 21:02:26,950] {standard_task_runner.py:76} INFO - Running: ['***', 'tasks', 'run', 'HomeWorkWeek2', 'csv_to_parquet', 'scheduled__2019-04-02T06:00:00+00:00', '--job-id', '310', '--raw', '--subdir', 'DAGS_FOLDER/dag_questions1.py', '--cfg-path', '/tmp/tmpckuss83z', '--error-file', '/tmp/tmp6m8ertll']
[2022-02-02 21:02:26,952] {standard_task_runner.py:77} INFO - Job 310: Subtask csv_to_parquet
[2022-02-02 21:02:27,161] {logging_mixin.py:109} INFO - Running <TaskInstance: HomeWorkWeek2.csv_to_parquet scheduled__2019-04-02T06:00:00+00:00 [running]> on host d574c7c5b085
[2022-02-02 21:02:27,305] {warnings.py:110} WARNING - /home/***/.local/lib/python3.7/site-packages/***/utils/context.py:152: AirflowContextDeprecationWarning: Accessing 'execution_date' from the template is deprecated and will be removed in a future version. Please use 'data_interval_start' or 'logical_date' instead.
  warnings.warn(_create_deprecation_warning(key, self._deprecation_replacements[key]))

[2022-02-02 21:02:27,356] {taskinstance.py:1426} INFO - Exporting the following env vars:
AIRFLOW_CTX_DAG_OWNER=***
AIRFLOW_CTX_DAG_ID=HomeWorkWeek2
AIRFLOW_CTX_TASK_ID=csv_to_parquet
AIRFLOW_CTX_EXECUTION_DATE=2019-04-02T06:00:00+00:00
AIRFLOW_CTX_DAG_RUN_ID=scheduled__2019-04-02T06:00:00+00:00
[2022-02-02 21:02:27,357] {taskinstance.py:1700} ERROR - Task failed with exception
Traceback (most recent call last):
  File "/home/airflow/.local/lib/python3.7/site-packages/airflow/models/taskinstance.py", line 1329, in _run_raw_task
    self._execute_task_with_callbacks(context)
  File "/home/airflow/.local/lib/python3.7/site-packages/airflow/models/taskinstance.py", line 1455, in _execute_task_with_callbacks
    result = self._execute_task(context, self.task)
  File "/home/airflow/.local/lib/python3.7/site-packages/airflow/models/taskinstance.py", line 1511, in _execute_task
    result = execute_callable(context=context)
  File "/home/airflow/.local/lib/python3.7/site-packages/airflow/operators/python.py", line 174, in execute
    return_value = self.execute_callable()
  File "/home/airflow/.local/lib/python3.7/site-packages/airflow/operators/python.py", line 185, in execute_callable
    return self.python_callable(*self.op_args, **self.op_kwargs)
  File "/opt/airflow/dags/ingest_fhv.py", line 17, in fhv_csv_to_parquet
    table = pv.read_csv(srcfile)
  File "pyarrow/_csv.pyx", line 862, in pyarrow._csv.read_csv
  File "pyarrow/_csv.pyx", line 755, in pyarrow._csv._get_reader
  File "pyarrow/io.pxi", line 1551, in pyarrow.lib.get_input_stream
  File "pyarrow/io.pxi", line 1522, in pyarrow.lib.get_native_file
  File "pyarrow/io.pxi", line 886, in pyarrow.lib.OSFile.__cinit__
  File "pyarrow/io.pxi", line 896, in pyarrow.lib.OSFile._open_readable
  File "pyarrow/error.pxi", line 143, in pyarrow.lib.pyarrow_internal_check_status
  File "pyarrow/error.pxi", line 112, in pyarrow.lib.check_status
FileNotFoundError: [Errno 2] Failed to open local file '/opt/airflowoutput_2019-04.csv'. Detail: [errno 2] No such file or directory
[2022-02-02 21:02:27,405] {taskinstance.py:1277} INFO - Marking task as FAILED. dag_id=HomeWorkWeek2, task_id=csv_to_parquet, execution_date=20190402T060000, start_date=20220202T210226, end_date=20220202T210227
[2022-02-02 21:02:27,453] {standard_task_runner.py:92} ERROR - Failed to execute job 310 for task csv_to_parquet
Traceback (most recent call last):
  File "/home/airflow/.local/lib/python3.7/site-packages/airflow/task/task_runner/standard_task_runner.py", line 85, in _start_by_fork
    args.func(args, dag=self.dag)
  File "/home/airflow/.local/lib/python3.7/site-packages/airflow/cli/cli_parser.py", line 48, in command
    return func(*args, **kwargs)
  File "/home/airflow/.local/lib/python3.7/site-packages/airflow/utils/cli.py", line 92, in wrapper
    return f(*args, **kwargs)
  File "/home/airflow/.local/lib/python3.7/site-packages/airflow/cli/commands/task_command.py", line 298, in task_run
    _run_task_by_selected_method(args, dag, ti)
  File "/home/airflow/.local/lib/python3.7/site-packages/airflow/cli/commands/task_command.py", line 107, in _run_task_by_selected_method
    _run_raw_task(args, ti)
  File "/home/airflow/.local/lib/python3.7/site-packages/airflow/cli/commands/task_command.py", line 184, in _run_raw_task
    error_file=args.error_file,
  File "/home/airflow/.local/lib/python3.7/site-packages/airflow/utils/session.py", line 70, in wrapper
    return func(*args, session=session, **kwargs)
  File "/home/airflow/.local/lib/python3.7/site-packages/airflow/models/taskinstance.py", line 1329, in _run_raw_task
    self._execute_task_with_callbacks(context)
  File "/home/airflow/.local/lib/python3.7/site-packages/airflow/models/taskinstance.py", line 1455, in _execute_task_with_callbacks
    result = self._execute_task(context, self.task)
  File "/home/airflow/.local/lib/python3.7/site-packages/airflow/models/taskinstance.py", line 1511, in _execute_task
    result = execute_callable(context=context)
  File "/home/airflow/.local/lib/python3.7/site-packages/airflow/operators/python.py", line 174, in execute
    return_value = self.execute_callable()
  File "/home/airflow/.local/lib/python3.7/site-packages/airflow/operators/python.py", line 185, in execute_callable
    return self.python_callable(*self.op_args, **self.op_kwargs)
  File "/opt/airflow/dags/ingest_fhv.py", line 17, in fhv_csv_to_parquet
    table = pv.read_csv(srcfile)
  File "pyarrow/_csv.pyx", line 862, in pyarrow._csv.read_csv
  File "pyarrow/_csv.pyx", line 755, in pyarrow._csv._get_reader
  File "pyarrow/io.pxi", line 1551, in pyarrow.lib.get_input_stream
  File "pyarrow/io.pxi", line 1522, in pyarrow.lib.get_native_file
  File "pyarrow/io.pxi", line 886, in pyarrow.lib.OSFile.__cinit__
  File "pyarrow/io.pxi", line 896, in pyarrow.lib.OSFile._open_readable
  File "pyarrow/error.pxi", line 143, in pyarrow.lib.pyarrow_internal_check_status
  File "pyarrow/error.pxi", line 112, in pyarrow.lib.check_status
FileNotFoundError: [Errno 2] Failed to open local file '/opt/airflowoutput_2019-04.csv'. Detail: [errno 2] No such file or directory
[2022-02-02 21:02:27,467] {local_task_job.py:154} INFO - Task exited with return code 1
[2022-02-02 21:02:27,627] {local_task_job.py:264} INFO - 0 downstream tasks scheduled from follow-on schedule check
