[2022-01-30 14:43:32,412] {taskinstance.py:1032} INFO - Dependencies all met for <TaskInstance: HomeWorkWeek2.dowdata manual__2022-01-30T14:38:25.264958+00:00 [queued]>
[2022-01-30 14:43:32,474] {taskinstance.py:1032} INFO - Dependencies all met for <TaskInstance: HomeWorkWeek2.dowdata manual__2022-01-30T14:38:25.264958+00:00 [queued]>
[2022-01-30 14:43:32,474] {taskinstance.py:1238} INFO - 
--------------------------------------------------------------------------------
[2022-01-30 14:43:32,475] {taskinstance.py:1239} INFO - Starting attempt 2 of 2
[2022-01-30 14:43:32,475] {taskinstance.py:1240} INFO - 
--------------------------------------------------------------------------------
[2022-01-30 14:43:32,565] {taskinstance.py:1259} INFO - Executing <Task(BashOperator): dowdata> on 2022-01-30 14:38:25.264958+00:00
[2022-01-30 14:43:32,577] {standard_task_runner.py:52} INFO - Started process 475 to run task
[2022-01-30 14:43:32,586] {standard_task_runner.py:76} INFO - Running: ['***', 'tasks', 'run', 'HomeWorkWeek2', 'dowdata', 'manual__2022-01-30T14:38:25.264958+00:00', '--job-id', '192', '--raw', '--subdir', 'DAGS_FOLDER/dag_questions1.py', '--cfg-path', '/tmp/tmpu7kaaj2k', '--error-file', '/tmp/tmpgn10advy']
[2022-01-30 14:43:32,589] {standard_task_runner.py:77} INFO - Job 192: Subtask dowdata
[2022-01-30 14:43:32,917] {logging_mixin.py:109} INFO - Running <TaskInstance: HomeWorkWeek2.dowdata manual__2022-01-30T14:38:25.264958+00:00 [running]> on host 785c0c715caa
[2022-01-30 14:43:33,138] {warnings.py:110} WARNING - /home/***/.local/lib/python3.7/site-packages/***/utils/context.py:152: AirflowContextDeprecationWarning: Accessing 'execution_date' from the template is deprecated and will be removed in a future version. Please use 'data_interval_start' or 'logical_date' instead.
  warnings.warn(_create_deprecation_warning(key, self._deprecation_replacements[key]))

[2022-01-30 14:43:33,187] {taskinstance.py:1426} INFO - Exporting the following env vars:
AIRFLOW_CTX_DAG_OWNER=***
AIRFLOW_CTX_DAG_ID=HomeWorkWeek2
AIRFLOW_CTX_TASK_ID=dowdata
AIRFLOW_CTX_EXECUTION_DATE=2022-01-30T14:38:25.264958+00:00
AIRFLOW_CTX_DAG_RUN_ID=manual__2022-01-30T14:38:25.264958+00:00
[2022-01-30 14:43:33,190] {subprocess.py:62} INFO - Tmp dir root location: 
 /tmp
[2022-01-30 14:43:33,194] {subprocess.py:74} INFO - Running command: ['bash', '-c', 'curl -sSLf https://s3.amazonaws.com/nyc-tlc/trip+data/yellow_tripdata_2022-01.csv > /opt/***output_2022-01.csv']
[2022-01-30 14:43:33,216] {subprocess.py:85} INFO - Output:
[2022-01-30 14:43:34,214] {subprocess.py:89} INFO - curl: (22) The requested URL returned error: 404 Not Found
[2022-01-30 14:43:34,222] {subprocess.py:93} INFO - Command exited with return code 22
[2022-01-30 14:43:34,307] {taskinstance.py:1700} ERROR - Task failed with exception
Traceback (most recent call last):
  File "/home/airflow/.local/lib/python3.7/site-packages/airflow/models/taskinstance.py", line 1329, in _run_raw_task
    self._execute_task_with_callbacks(context)
  File "/home/airflow/.local/lib/python3.7/site-packages/airflow/models/taskinstance.py", line 1455, in _execute_task_with_callbacks
    result = self._execute_task(context, self.task)
  File "/home/airflow/.local/lib/python3.7/site-packages/airflow/models/taskinstance.py", line 1511, in _execute_task
    result = execute_callable(context=context)
  File "/home/airflow/.local/lib/python3.7/site-packages/airflow/operators/bash.py", line 188, in execute
    f'Bash command failed. The command returned a non-zero exit code {result.exit_code}.'
airflow.exceptions.AirflowException: Bash command failed. The command returned a non-zero exit code 22.
[2022-01-30 14:43:34,376] {taskinstance.py:1277} INFO - Marking task as FAILED. dag_id=HomeWorkWeek2, task_id=dowdata, execution_date=20220130T143825, start_date=20220130T144332, end_date=20220130T144334
[2022-01-30 14:43:34,441] {standard_task_runner.py:92} ERROR - Failed to execute job 192 for task dowdata
Traceback (most recent call last):
  File "/home/airflow/.local/lib/python3.7/site-packages/airflow/task/task_runner/standard_task_runner.py", line 85, in _start_by_fork
    args.func(args, dag=self.dag)
  File "/home/airflow/.local/lib/python3.7/site-packages/airflow/cli/cli_parser.py", line 48, in command
    return func(*args, **kwargs)
  File "/home/airflow/.local/lib/python3.7/site-packages/airflow/utils/cli.py", line 92, in wrapper
    return f(*args, **kwargs)
  File "/home/airflow/.local/lib/python3.7/site-packages/airflow/cli/commands/task_command.py", line 298, in task_run
    _run_task_by_selected_method(args, dag, ti)
  File "/home/airflow/.local/lib/python3.7/site-packages/airflow/cli/commands/task_command.py", line 107, in _run_task_by_selected_method
    _run_raw_task(args, ti)
  File "/home/airflow/.local/lib/python3.7/site-packages/airflow/cli/commands/task_command.py", line 184, in _run_raw_task
    error_file=args.error_file,
  File "/home/airflow/.local/lib/python3.7/site-packages/airflow/utils/session.py", line 70, in wrapper
    return func(*args, session=session, **kwargs)
  File "/home/airflow/.local/lib/python3.7/site-packages/airflow/models/taskinstance.py", line 1329, in _run_raw_task
    self._execute_task_with_callbacks(context)
  File "/home/airflow/.local/lib/python3.7/site-packages/airflow/models/taskinstance.py", line 1455, in _execute_task_with_callbacks
    result = self._execute_task(context, self.task)
  File "/home/airflow/.local/lib/python3.7/site-packages/airflow/models/taskinstance.py", line 1511, in _execute_task
    result = execute_callable(context=context)
  File "/home/airflow/.local/lib/python3.7/site-packages/airflow/operators/bash.py", line 188, in execute
    f'Bash command failed. The command returned a non-zero exit code {result.exit_code}.'
airflow.exceptions.AirflowException: Bash command failed. The command returned a non-zero exit code 22.
[2022-01-30 14:43:34,527] {local_task_job.py:154} INFO - Task exited with return code 1
[2022-01-30 14:43:34,752] {local_task_job.py:264} INFO - 0 downstream tasks scheduled from follow-on schedule check
