[2022-01-30 14:36:41,296] {taskinstance.py:1032} INFO - Dependencies all met for <TaskInstance: HomeWorkWeek2.dowdata scheduled__2021-12-02T06:00:00+00:00 [queued]>
[2022-01-30 14:36:41,358] {taskinstance.py:1032} INFO - Dependencies all met for <TaskInstance: HomeWorkWeek2.dowdata scheduled__2021-12-02T06:00:00+00:00 [queued]>
[2022-01-30 14:36:41,359] {taskinstance.py:1238} INFO - 
--------------------------------------------------------------------------------
[2022-01-30 14:36:41,359] {taskinstance.py:1239} INFO - Starting attempt 2 of 2
[2022-01-30 14:36:41,360] {taskinstance.py:1240} INFO - 
--------------------------------------------------------------------------------
[2022-01-30 14:36:41,456] {taskinstance.py:1259} INFO - Executing <Task(BashOperator): dowdata> on 2021-12-02 06:00:00+00:00
[2022-01-30 14:36:41,470] {standard_task_runner.py:52} INFO - Started process 81 to run task
[2022-01-30 14:36:41,486] {standard_task_runner.py:76} INFO - Running: ['***', 'tasks', 'run', 'HomeWorkWeek2', 'dowdata', 'scheduled__2021-12-02T06:00:00+00:00', '--job-id', '178', '--raw', '--subdir', 'DAGS_FOLDER/dag_questions1.py', '--cfg-path', '/tmp/tmpe25wp8zx', '--error-file', '/tmp/tmpw2iwqz7q']
[2022-01-30 14:36:41,488] {standard_task_runner.py:77} INFO - Job 178: Subtask dowdata
[2022-01-30 14:36:41,712] {logging_mixin.py:109} INFO - Running <TaskInstance: HomeWorkWeek2.dowdata scheduled__2021-12-02T06:00:00+00:00 [running]> on host 785c0c715caa
[2022-01-30 14:36:41,905] {warnings.py:110} WARNING - /home/***/.local/lib/python3.7/site-packages/***/utils/context.py:152: AirflowContextDeprecationWarning: Accessing 'execution_date' from the template is deprecated and will be removed in a future version. Please use 'data_interval_start' or 'logical_date' instead.
  warnings.warn(_create_deprecation_warning(key, self._deprecation_replacements[key]))

[2022-01-30 14:36:42,020] {taskinstance.py:1426} INFO - Exporting the following env vars:
AIRFLOW_CTX_DAG_OWNER=***
AIRFLOW_CTX_DAG_ID=HomeWorkWeek2
AIRFLOW_CTX_TASK_ID=dowdata
AIRFLOW_CTX_EXECUTION_DATE=2021-12-02T06:00:00+00:00
AIRFLOW_CTX_DAG_RUN_ID=scheduled__2021-12-02T06:00:00+00:00
[2022-01-30 14:36:42,022] {subprocess.py:62} INFO - Tmp dir root location: 
 /tmp
[2022-01-30 14:36:42,042] {subprocess.py:74} INFO - Running command: ['bash', '-c', 'curl -sSLf https://s3.amazonaws.com/nyc-tlc/trip+data/yellow_tripdata_2021-12.csv > /opt/***output_2021-12.csv']
[2022-01-30 14:36:42,098] {subprocess.py:85} INFO - Output:
[2022-01-30 14:36:43,170] {subprocess.py:89} INFO - curl: (22) The requested URL returned error: 404 Not Found
[2022-01-30 14:36:43,171] {subprocess.py:93} INFO - Command exited with return code 22
[2022-01-30 14:36:43,193] {taskinstance.py:1700} ERROR - Task failed with exception
Traceback (most recent call last):
  File "/home/airflow/.local/lib/python3.7/site-packages/airflow/models/taskinstance.py", line 1329, in _run_raw_task
    self._execute_task_with_callbacks(context)
  File "/home/airflow/.local/lib/python3.7/site-packages/airflow/models/taskinstance.py", line 1455, in _execute_task_with_callbacks
    result = self._execute_task(context, self.task)
  File "/home/airflow/.local/lib/python3.7/site-packages/airflow/models/taskinstance.py", line 1511, in _execute_task
    result = execute_callable(context=context)
  File "/home/airflow/.local/lib/python3.7/site-packages/airflow/operators/bash.py", line 188, in execute
    f'Bash command failed. The command returned a non-zero exit code {result.exit_code}.'
airflow.exceptions.AirflowException: Bash command failed. The command returned a non-zero exit code 22.
[2022-01-30 14:36:43,203] {taskinstance.py:1277} INFO - Marking task as FAILED. dag_id=HomeWorkWeek2, task_id=dowdata, execution_date=20211202T060000, start_date=20220130T143641, end_date=20220130T143643
[2022-01-30 14:36:43,279] {standard_task_runner.py:92} ERROR - Failed to execute job 178 for task dowdata
Traceback (most recent call last):
  File "/home/airflow/.local/lib/python3.7/site-packages/airflow/task/task_runner/standard_task_runner.py", line 85, in _start_by_fork
    args.func(args, dag=self.dag)
  File "/home/airflow/.local/lib/python3.7/site-packages/airflow/cli/cli_parser.py", line 48, in command
    return func(*args, **kwargs)
  File "/home/airflow/.local/lib/python3.7/site-packages/airflow/utils/cli.py", line 92, in wrapper
    return f(*args, **kwargs)
  File "/home/airflow/.local/lib/python3.7/site-packages/airflow/cli/commands/task_command.py", line 298, in task_run
    _run_task_by_selected_method(args, dag, ti)
  File "/home/airflow/.local/lib/python3.7/site-packages/airflow/cli/commands/task_command.py", line 107, in _run_task_by_selected_method
    _run_raw_task(args, ti)
  File "/home/airflow/.local/lib/python3.7/site-packages/airflow/cli/commands/task_command.py", line 184, in _run_raw_task
    error_file=args.error_file,
  File "/home/airflow/.local/lib/python3.7/site-packages/airflow/utils/session.py", line 70, in wrapper
    return func(*args, session=session, **kwargs)
  File "/home/airflow/.local/lib/python3.7/site-packages/airflow/models/taskinstance.py", line 1329, in _run_raw_task
    self._execute_task_with_callbacks(context)
  File "/home/airflow/.local/lib/python3.7/site-packages/airflow/models/taskinstance.py", line 1455, in _execute_task_with_callbacks
    result = self._execute_task(context, self.task)
  File "/home/airflow/.local/lib/python3.7/site-packages/airflow/models/taskinstance.py", line 1511, in _execute_task
    result = execute_callable(context=context)
  File "/home/airflow/.local/lib/python3.7/site-packages/airflow/operators/bash.py", line 188, in execute
    f'Bash command failed. The command returned a non-zero exit code {result.exit_code}.'
airflow.exceptions.AirflowException: Bash command failed. The command returned a non-zero exit code 22.
[2022-01-30 14:36:43,325] {local_task_job.py:154} INFO - Task exited with return code 1
[2022-01-30 14:36:43,466] {local_task_job.py:264} INFO - 0 downstream tasks scheduled from follow-on schedule check
[2022-01-30 15:50:55,593] {taskinstance.py:1032} INFO - Dependencies all met for <TaskInstance: HomeWorkWeek2.dowdata scheduled__2021-12-02T06:00:00+00:00 [queued]>
[2022-01-30 15:50:55,635] {taskinstance.py:1032} INFO - Dependencies all met for <TaskInstance: HomeWorkWeek2.dowdata scheduled__2021-12-02T06:00:00+00:00 [queued]>
[2022-01-30 15:50:55,636] {taskinstance.py:1238} INFO - 
--------------------------------------------------------------------------------
[2022-01-30 15:50:55,636] {taskinstance.py:1239} INFO - Starting attempt 2 of 2
[2022-01-30 15:50:55,637] {taskinstance.py:1240} INFO - 
--------------------------------------------------------------------------------
[2022-01-30 15:50:55,691] {taskinstance.py:1259} INFO - Executing <Task(BashOperator): dowdata> on 2021-12-02 06:00:00+00:00
[2022-01-30 15:50:55,707] {standard_task_runner.py:52} INFO - Started process 109 to run task
[2022-01-30 15:50:55,723] {standard_task_runner.py:76} INFO - Running: ['***', 'tasks', 'run', 'HomeWorkWeek2', 'dowdata', 'scheduled__2021-12-02T06:00:00+00:00', '--job-id', '284', '--raw', '--subdir', 'DAGS_FOLDER/dag_questions1.py', '--cfg-path', '/tmp/tmpjy_ce4q_', '--error-file', '/tmp/tmpa1eluh6l']
[2022-01-30 15:50:55,740] {standard_task_runner.py:77} INFO - Job 284: Subtask dowdata
[2022-01-30 15:50:56,282] {logging_mixin.py:109} INFO - Running <TaskInstance: HomeWorkWeek2.dowdata scheduled__2021-12-02T06:00:00+00:00 [running]> on host 76a6ca5a1f6b
[2022-01-30 15:50:56,515] {warnings.py:110} WARNING - /home/***/.local/lib/python3.7/site-packages/***/utils/context.py:152: AirflowContextDeprecationWarning: Accessing 'execution_date' from the template is deprecated and will be removed in a future version. Please use 'data_interval_start' or 'logical_date' instead.
  warnings.warn(_create_deprecation_warning(key, self._deprecation_replacements[key]))

[2022-01-30 15:50:56,620] {taskinstance.py:1426} INFO - Exporting the following env vars:
AIRFLOW_CTX_DAG_OWNER=***
AIRFLOW_CTX_DAG_ID=HomeWorkWeek2
AIRFLOW_CTX_TASK_ID=dowdata
AIRFLOW_CTX_EXECUTION_DATE=2021-12-02T06:00:00+00:00
AIRFLOW_CTX_DAG_RUN_ID=scheduled__2021-12-02T06:00:00+00:00
[2022-01-30 15:50:56,623] {subprocess.py:62} INFO - Tmp dir root location: 
 /tmp
[2022-01-30 15:50:56,633] {subprocess.py:74} INFO - Running command: ['bash', '-c', 'curl -sSLf https://s3.amazonaws.com/nyc-tlc/trip+data/yellow_tripdata_2021-12.csv > /opt/***output_2021-12.csv']
[2022-01-30 15:50:56,674] {subprocess.py:85} INFO - Output:
[2022-01-30 15:50:57,749] {subprocess.py:89} INFO - curl: (22) The requested URL returned error: 404 Not Found
[2022-01-30 15:50:57,755] {subprocess.py:93} INFO - Command exited with return code 22
[2022-01-30 15:50:58,157] {taskinstance.py:1700} ERROR - Task failed with exception
Traceback (most recent call last):
  File "/home/airflow/.local/lib/python3.7/site-packages/airflow/models/taskinstance.py", line 1329, in _run_raw_task
    self._execute_task_with_callbacks(context)
  File "/home/airflow/.local/lib/python3.7/site-packages/airflow/models/taskinstance.py", line 1455, in _execute_task_with_callbacks
    result = self._execute_task(context, self.task)
  File "/home/airflow/.local/lib/python3.7/site-packages/airflow/models/taskinstance.py", line 1511, in _execute_task
    result = execute_callable(context=context)
  File "/home/airflow/.local/lib/python3.7/site-packages/airflow/operators/bash.py", line 188, in execute
    f'Bash command failed. The command returned a non-zero exit code {result.exit_code}.'
airflow.exceptions.AirflowException: Bash command failed. The command returned a non-zero exit code 22.
[2022-01-30 15:50:58,196] {taskinstance.py:1277} INFO - Marking task as FAILED. dag_id=HomeWorkWeek2, task_id=dowdata, execution_date=20211202T060000, start_date=20220130T155055, end_date=20220130T155058
[2022-01-30 15:50:58,291] {standard_task_runner.py:92} ERROR - Failed to execute job 284 for task dowdata
Traceback (most recent call last):
  File "/home/airflow/.local/lib/python3.7/site-packages/airflow/task/task_runner/standard_task_runner.py", line 85, in _start_by_fork
    args.func(args, dag=self.dag)
  File "/home/airflow/.local/lib/python3.7/site-packages/airflow/cli/cli_parser.py", line 48, in command
    return func(*args, **kwargs)
  File "/home/airflow/.local/lib/python3.7/site-packages/airflow/utils/cli.py", line 92, in wrapper
    return f(*args, **kwargs)
  File "/home/airflow/.local/lib/python3.7/site-packages/airflow/cli/commands/task_command.py", line 298, in task_run
    _run_task_by_selected_method(args, dag, ti)
  File "/home/airflow/.local/lib/python3.7/site-packages/airflow/cli/commands/task_command.py", line 107, in _run_task_by_selected_method
    _run_raw_task(args, ti)
  File "/home/airflow/.local/lib/python3.7/site-packages/airflow/cli/commands/task_command.py", line 184, in _run_raw_task
    error_file=args.error_file,
  File "/home/airflow/.local/lib/python3.7/site-packages/airflow/utils/session.py", line 70, in wrapper
    return func(*args, session=session, **kwargs)
  File "/home/airflow/.local/lib/python3.7/site-packages/airflow/models/taskinstance.py", line 1329, in _run_raw_task
    self._execute_task_with_callbacks(context)
  File "/home/airflow/.local/lib/python3.7/site-packages/airflow/models/taskinstance.py", line 1455, in _execute_task_with_callbacks
    result = self._execute_task(context, self.task)
  File "/home/airflow/.local/lib/python3.7/site-packages/airflow/models/taskinstance.py", line 1511, in _execute_task
    result = execute_callable(context=context)
  File "/home/airflow/.local/lib/python3.7/site-packages/airflow/operators/bash.py", line 188, in execute
    f'Bash command failed. The command returned a non-zero exit code {result.exit_code}.'
airflow.exceptions.AirflowException: Bash command failed. The command returned a non-zero exit code 22.
[2022-01-30 15:50:58,332] {local_task_job.py:154} INFO - Task exited with return code 1
[2022-01-30 15:50:58,711] {local_task_job.py:264} INFO - 0 downstream tasks scheduled from follow-on schedule check
